<?xml version="1.0" ?>
<robot name="BodyIsolate" xmlns:xacro="http://www.ros.org/wiki/xacro">

<xacro:include filename="$(find BodyIsolate_description)/urdf/materials.xacro" />
<xacro:include filename="$(find BodyIsolate_description)/urdf/BodyIsolate.trans" />
<xacro:include filename="$(find BodyIsolate_description)/urdf/BodyIsolate.gazebo" />
<link name="base_link">
  <inertial>
    <origin xyz="0.0009294833926678864 -0.007865537027084635 -0.0009793609078232745" rpy="0 0 0"/>
    <mass value="7.794810015152198"/>
    <inertia ixx="0.025672" iyy="0.135211" izz="0.143448" ixy="-0.0" iyz="0.0" ixz="-5.3e-05"/>
  </inertial>
  <visual>
    <origin xyz="0 0 0" rpy="0 0 0"/>
    <geometry>
      <mesh filename="package://BodyIsolate_description/meshes/base_link.stl" scale="0.001 0.001 0.001"/>
    </geometry>
    <material name="silver"/>
  </visual>
  <collision>
    <origin xyz="0 0 0" rpy="0 0 0"/>
    <geometry>
      <mesh filename="package://BodyIsolate_description/meshes/base_link.stl" scale="0.001 0.001 0.001"/>
    </geometry>
  </collision>
</link>

<link name="LF_shoulder_1">
  <inertial>
    <origin xyz="0.02483325275447823 0.024789583593927474 -0.0012078159033472617" rpy="0 0 0"/>
    <mass value="0.7519601881634892"/>
    <inertia ixx="0.00093" iyy="0.000429" izz="0.00081" ixy="-0.000109" iyz="-0.000161" ixz="-6e-05"/>
  </inertial>
  <visual>
    <origin xyz="-0.10802 -0.057134 -0.008245" rpy="0 0 0"/>
    <geometry>
      <mesh filename="package://BodyIsolate_description/meshes/LF_shoulder_1.stl" scale="0.001 0.001 0.001"/>
    </geometry>
    <material name="silver"/>
  </visual>
  <collision>
    <origin xyz="-0.10802 -0.057134 -0.008245" rpy="0 0 0"/>
    <geometry>
      <mesh filename="package://BodyIsolate_description/meshes/LF_shoulder_1.stl" scale="0.001 0.001 0.001"/>
    </geometry>
  </collision>
</link>

<link name="RF_shoulder_1">
  <inertial>
    <origin xyz="0.024833248126540614 -0.024788628815191754 -0.0012078111368774439" rpy="0 0 0"/>
    <mass value="0.7519609779147036"/>
    <inertia ixx="0.00093" iyy="0.000429" izz="0.00081" ixy="0.000109" iyz="0.000161" ixz="-6e-05"/>
  </inertial>
  <visual>
    <origin xyz="-0.10802 0.072866 -0.008245" rpy="0 0 0"/>
    <geometry>
      <mesh filename="package://BodyIsolate_description/meshes/RF_shoulder_1.stl" scale="0.001 0.001 0.001"/>
    </geometry>
    <material name="silver"/>
  </visual>
  <collision>
    <origin xyz="-0.10802 0.072866 -0.008245" rpy="0 0 0"/>
    <geometry>
      <mesh filename="package://BodyIsolate_description/meshes/RF_shoulder_1.stl" scale="0.001 0.001 0.001"/>
    </geometry>
  </collision>
</link>

<link name="LR_shoulder_1">
  <inertial>
    <origin xyz="0.024833252754477925 0.024789583593927737 -0.0012078159033466736" rpy="0 0 0"/>
    <mass value="0.7519601881635138"/>
    <inertia ixx="0.00093" iyy="0.000429" izz="0.00081" ixy="-0.000109" iyz="-0.000161" ixz="-6e-05"/>
  </inertial>
  <visual>
    <origin xyz="0.16928 -0.057134 -0.008245" rpy="0 0 0"/>
    <geometry>
      <mesh filename="package://BodyIsolate_description/meshes/LR_shoulder_1.stl" scale="0.001 0.001 0.001"/>
    </geometry>
    <material name="silver"/>
  </visual>
  <collision>
    <origin xyz="0.16928 -0.057134 -0.008245" rpy="0 0 0"/>
    <geometry>
      <mesh filename="package://BodyIsolate_description/meshes/LR_shoulder_1.stl" scale="0.001 0.001 0.001"/>
    </geometry>
  </collision>
</link>

<link name="RR_shoulder_1">
  <inertial>
    <origin xyz="0.024833248126540308 -0.024788628815192962 -0.001207811136879954" rpy="0 0 0"/>
    <mass value="0.7519609779146718"/>
    <inertia ixx="0.00093" iyy="0.000429" izz="0.00081" ixy="0.000109" iyz="0.000161" ixz="-6e-05"/>
  </inertial>
  <visual>
    <origin xyz="0.16928 0.072866 -0.008245" rpy="0 0 0"/>
    <geometry>
      <mesh filename="package://BodyIsolate_description/meshes/RR_shoulder_1.stl" scale="0.001 0.001 0.001"/>
    </geometry>
    <material name="silver"/>
  </visual>
  <collision>
    <origin xyz="0.16928 0.072866 -0.008245" rpy="0 0 0"/>
    <geometry>
      <mesh filename="package://BodyIsolate_description/meshes/RR_shoulder_1.stl" scale="0.001 0.001 0.001"/>
    </geometry>
  </collision>
</link>

<link name="LF_upper_leg_1">
  <inertial>
    <origin xyz="0.0010223181011703997 -0.02122322452806688 -0.0653876247063408" rpy="0 0 0"/>
    <mass value="1.0458484256600535"/>
    <inertia ixx="0.003088" iyy="0.00296" izz="0.000565" ixy="1.3e-05" iyz="-3.3e-05" ixz="9.7e-05"/>
  </inertial>
  <visual>
    <origin xyz="-0.12892 -0.148834 -0.008245" rpy="0 0 0"/>
    <geometry>
      <mesh filename="package://BodyIsolate_description/meshes/LF_upper_leg_1.stl" scale="0.001 0.001 0.001"/>
    </geometry>
    <material name="silver"/>
  </visual>
  <collision>
    <origin xyz="-0.12892 -0.148834 -0.008245" rpy="0 0 0"/>
    <geometry>
      <mesh filename="package://BodyIsolate_description/meshes/LF_upper_leg_1.stl" scale="0.001 0.001 0.001"/>
    </geometry>
  </collision>
</link>

<link name="RF_upper_leg_1">
  <inertial>
    <origin xyz="0.0010224410536952278 0.021223711599720807 -0.06538622105271431" rpy="0 0 0"/>
    <mass value="1.0458654261286338"/>
    <inertia ixx="0.003088" iyy="0.00296" izz="0.000565" ixy="-1.3e-05" iyz="3.3e-05" ixz="9.7e-05"/>
  </inertial>
  <visual>
    <origin xyz="-0.12892 0.164566 -0.008245" rpy="0 0 0"/>
    <geometry>
      <mesh filename="package://BodyIsolate_description/meshes/RF_upper_leg_1.stl" scale="0.001 0.001 0.001"/>
    </geometry>
    <material name="silver"/>
  </visual>
  <collision>
    <origin xyz="-0.12892 0.164566 -0.008245" rpy="0 0 0"/>
    <geometry>
      <mesh filename="package://BodyIsolate_description/meshes/RF_upper_leg_1.stl" scale="0.001 0.001 0.001"/>
    </geometry>
  </collision>
</link>

<link name="RR_upper_leg_1">
  <inertial>
    <origin xyz="0.0010224410524758698 0.02122371159972017 -0.06538622105271566" rpy="0 0 0"/>
    <mass value="1.0458654261286542"/>
    <inertia ixx="0.003088" iyy="0.00296" izz="0.000565" ixy="-1.3e-05" iyz="3.3e-05" ixz="9.7e-05"/>
  </inertial>
  <visual>
    <origin xyz="0.14838 0.164566 -0.008245" rpy="0 0 0"/>
    <geometry>
      <mesh filename="package://BodyIsolate_description/meshes/RR_upper_leg_1.stl" scale="0.001 0.001 0.001"/>
    </geometry>
    <material name="silver"/>
  </visual>
  <collision>
    <origin xyz="0.14838 0.164566 -0.008245" rpy="0 0 0"/>
    <geometry>
      <mesh filename="package://BodyIsolate_description/meshes/RR_upper_leg_1.stl" scale="0.001 0.001 0.001"/>
    </geometry>
  </collision>
</link>

<link name="LR_upper_leg_1">
  <inertial>
    <origin xyz="0.0010223181013646054 -0.021223224528065382 -0.06538762470634304" rpy="0 0 0"/>
    <mass value="1.0458484256600902"/>
    <inertia ixx="0.003088" iyy="0.00296" izz="0.000565" ixy="1.3e-05" iyz="-3.3e-05" ixz="9.7e-05"/>
  </inertial>
  <visual>
    <origin xyz="0.14838 -0.148834 -0.008245" rpy="0 0 0"/>
    <geometry>
      <mesh filename="package://BodyIsolate_description/meshes/LR_upper_leg_1.stl" scale="0.001 0.001 0.001"/>
    </geometry>
    <material name="silver"/>
  </visual>
  <collision>
    <origin xyz="0.14838 -0.148834 -0.008245" rpy="0 0 0"/>
    <geometry>
      <mesh filename="package://BodyIsolate_description/meshes/LR_upper_leg_1.stl" scale="0.001 0.001 0.001"/>
    </geometry>
  </collision>
</link>

<link name="LF_lower_leg_1">
  <inertial>
    <origin xyz="0.007439395719606973 -0.023891955972947132 -0.07198444745387553" rpy="0 0 0"/>
    <mass value="1.0996050742499592"/>
    <inertia ixx="0.003723" iyy="0.003768" izz="0.000289" ixy="4e-06" iyz="-2.2e-05" ixz="0.000207"/>
  </inertial>
  <visual>
    <origin xyz="-0.14892 -0.156984 0.140415" rpy="0 0 0"/>
    <geometry>
      <mesh filename="package://BodyIsolate_description/meshes/LF_lower_leg_1.stl" scale="0.001 0.001 0.001"/>
    </geometry>
    <material name="silver"/>
  </visual>
  <collision>
    <origin xyz="-0.14892 -0.156984 0.140415" rpy="0 0 0"/>
    <geometry>
      <mesh filename="package://BodyIsolate_description/meshes/LF_lower_leg_1.stl" scale="0.001 0.001 0.001"/>
    </geometry>
  </collision>
</link>

<link name="RF_lower_leg_1">
  <inertial>
    <origin xyz="0.007439392221484098 0.023892885345322662 -0.07198444174015034" rpy="0 0 0"/>
    <mass value="1.0996043860818394"/>
    <inertia ixx="0.003723" iyy="0.003768" izz="0.000289" ixy="-4e-06" iyz="2.2e-05" ixz="0.000207"/>
  </inertial>
  <visual>
    <origin xyz="-0.14892 0.172716 0.140415" rpy="0 0 0"/>
    <geometry>
      <mesh filename="package://BodyIsolate_description/meshes/RF_lower_leg_1.stl" scale="0.001 0.001 0.001"/>
    </geometry>
    <material name="silver"/>
  </visual>
  <collision>
    <origin xyz="-0.14892 0.172716 0.140415" rpy="0 0 0"/>
    <geometry>
      <mesh filename="package://BodyIsolate_description/meshes/RF_lower_leg_1.stl" scale="0.001 0.001 0.001"/>
    </geometry>
  </collision>
</link>

<link name="RR_lower_leg_1">
  <inertial>
    <origin xyz="0.007439392221484195 0.02389288534532258 -0.07198444174015028" rpy="0 0 0"/>
    <mass value="1.099604386081836"/>
    <inertia ixx="0.003723" iyy="0.003768" izz="0.000289" ixy="-4e-06" iyz="2.2e-05" ixz="0.000207"/>
  </inertial>
  <visual>
    <origin xyz="0.12838 0.172716 0.140415" rpy="0 0 0"/>
    <geometry>
      <mesh filename="package://BodyIsolate_description/meshes/RR_lower_leg_1.stl" scale="0.001 0.001 0.001"/>
    </geometry>
    <material name="silver"/>
  </visual>
  <collision>
    <origin xyz="0.12838 0.172716 0.140415" rpy="0 0 0"/>
    <geometry>
      <mesh filename="package://BodyIsolate_description/meshes/RR_lower_leg_1.stl" scale="0.001 0.001 0.001"/>
    </geometry>
  </collision>
</link>

<link name="LR_lower_leg_1">
  <inertial>
    <origin xyz="0.007439395719606473 -0.023891955972947132 -0.0719844474538755" rpy="0 0 0"/>
    <mass value="1.0996050742499566"/>
    <inertia ixx="0.003723" iyy="0.003768" izz="0.000289" ixy="4e-06" iyz="-2.2e-05" ixz="0.000207"/>
  </inertial>
  <visual>
    <origin xyz="0.12838 -0.156984 0.140415" rpy="0 0 0"/>
    <geometry>
      <mesh filename="package://BodyIsolate_description/meshes/LR_lower_leg_1.stl" scale="0.001 0.001 0.001"/>
    </geometry>
    <material name="silver"/>
  </visual>
  <collision>
    <origin xyz="0.12838 -0.156984 0.140415" rpy="0 0 0"/>
    <geometry>
      <mesh filename="package://BodyIsolate_description/meshes/LR_lower_leg_1.stl" scale="0.001 0.001 0.001"/>
    </geometry>
  </collision>
</link>

<joint name="LF_hip" type="continuous">
  <origin xyz="0.10802 0.057134 0.008245" rpy="0 0 0"/>
  <parent link="base_link"/>
  <child link="LF_shoulder_1"/>
  <axis xyz="1.0 0.0 -0.0"/>
</joint>

<joint name="RF_hip" type="continuous">
  <origin xyz="0.10802 -0.072866 0.008245" rpy="0 0 0"/>
  <parent link="base_link"/>
  <child link="RF_shoulder_1"/>
  <axis xyz="-1.0 -0.0 0.0"/>
</joint>

<joint name="LR_hip" type="continuous">
  <origin xyz="-0.16928 0.057134 0.008245" rpy="0 0 0"/>
  <parent link="base_link"/>
  <child link="LR_shoulder_1"/>
  <axis xyz="1.0 0.0 -0.0"/>
</joint>

<joint name="RR_hip" type="continuous">
  <origin xyz="-0.16928 -0.072866 0.008245" rpy="0 0 0"/>
  <parent link="base_link"/>
  <child link="RR_shoulder_1"/>
  <axis xyz="-1.0 -0.0 0.0"/>
</joint>

<joint name="LF_shoulder" type="continuous">
  <origin xyz="0.0209 0.0917 0.0" rpy="0 0 0"/>
  <parent link="LF_shoulder_1"/>
  <child link="LF_upper_leg_1"/>
  <axis xyz="0.0 -1.0 0.0"/>
</joint>

<joint name="RF_shoulder" type="continuous">
  <origin xyz="0.0209 -0.0917 0.0" rpy="0 0 0"/>
  <parent link="RF_shoulder_1"/>
  <child link="RF_upper_leg_1"/>
  <axis xyz="0.0 -1.0 0.0"/>
</joint>

<joint name="RR_shoulder" type="continuous">
  <origin xyz="0.0209 -0.0917 0.0" rpy="0 0 0"/>
  <parent link="RR_shoulder_1"/>
  <child link="RR_upper_leg_1"/>
  <axis xyz="0.0 -1.0 0.0"/>
</joint>

<joint name="LR_shoulder" type="continuous">
  <origin xyz="0.0209 0.0917 0.0" rpy="0 0 0"/>
  <parent link="LR_shoulder_1"/>
  <child link="LR_upper_leg_1"/>
  <axis xyz="0.0 -1.0 0.0"/>
</joint>

<joint name="LF_elbow" type="continuous">
  <origin xyz="0.02 0.00815 -0.14866" rpy="0 0 0"/>
  <parent link="LF_upper_leg_1"/>
  <child link="LF_lower_leg_1"/>
  <axis xyz="0.0 -1.0 0.0"/>
</joint>

<joint name="RF_elbow" type="continuous">
  <origin xyz="0.02 -0.00815 -0.14866" rpy="0 0 0"/>
  <parent link="RF_upper_leg_1"/>
  <child link="RF_lower_leg_1"/>
  <axis xyz="0.0 -1.0 0.0"/>
</joint>

<joint name="RR_elbow" type="continuous">
  <origin xyz="0.02 -0.00815 -0.14866" rpy="0 0 0"/>
  <parent link="RR_upper_leg_1"/>
  <child link="RR_lower_leg_1"/>
  <axis xyz="0.0 -1.0 0.0"/>
</joint>

<joint name="LR_elbow" type="continuous">
  <origin xyz="0.02 0.00815 -0.14866" rpy="0 0 0"/>
  <parent link="LR_upper_leg_1"/>
  <child link="LR_lower_leg_1"/>
  <axis xyz="0.0 -1.0 0.0"/>
</joint>

</robot>
